<?xml version="1.0" encoding="utf-8"?>
<robot xmlns:xacro="http://www.ros.org/wiki/xacro"  name="robot">
  <link
    name="base_link">
    <!-- <inertial>
      <origin
        xyz="0 0 0"
        rpy="0 0 0" />
      <mass
        value="0" />
      <inertia
        ixx="0"
        ixy="0"
        ixz="0"
        iyy="0"
        iyz="0"
        izz="0" />
    </inertial> -->
    <visual>
      <origin
        xyz="0 0 0"
        rpy="0 0 0" />
      <geometry>
        <mesh
          filename="package://gf3_description/meshes/base_link.STL" />
      </geometry>
      <material
        name="">
        <color
          rgba="0.75294 0.75294 0.75294 1" />
      </material>
    </visual>
    <collision>
      <origin
        xyz="0 0 0"
        rpy="0 0 0" />
      <geometry>
        <mesh
          filename="package://gf3_description/meshes/base_link.STL" />
      </geometry>
    </collision>
  </link>
  <link
    name="shoulder_1">
    <!-- <inertial>
      <origin
        xyz="0.143483235103531 0.0250123355737991 0.702729587168112"
        rpy="0 0 0" />
      <mass
        value="0.304968955908777" />
      <inertia
        ixx="0.000195934222549376"
        ixy="3.62075870294881E-13"
        ixz="-1.32765952891061E-06"
        iyy="0.000161270839111698"
        iyz="9.38593559269322E-12"
        izz="0.000184029805378281" />
    </inertial> -->
    <visual>
      <origin
        xyz="0 0 0"
        rpy="0 0 0" />
      <geometry>
        <mesh
          filename="package://gf3_description/meshes/shoulder_1.STL" />
      </geometry>
      <material
        name="">
        <color
          rgba="0.752941176470588 0.752941176470588 0.752941176470588 1" />
      </material>
    </visual>
    <collision>
      <origin
        xyz="0 0 0"
        rpy="0 0 0" />
      <geometry>
        <mesh
          filename="package://gf3_description/meshes/shoulder_1.STL" />
      </geometry>
    </collision>
  </link>
  <joint
    name="base_link_shoulder_1"
    type="fixed">
    <origin
      xyz="0 0 0"
      rpy="0 0 0" />
    <parent
      link="base_link" />
    <child
      link="shoulder_1" />
    <axis
      xyz="0 0 0" />
  </joint>
  <link
    name="shoulder_2">
    <inertial>
      <origin
        xyz="-0.00935681252853031 0.079150572505589 -0.0597717888530282"
        rpy="0 0 0" />
      <mass
        value="0.402167431900124" />
      <inertia
        ixx="0.000681722421314581"
        ixy="2.94723633624945E-05"
        ixz="-2.53719087675482E-06"
        iyy="0.000446003101679024"
        iyz="0.000188270353164379"
        izz="0.000665910291514535" />
    </inertial>
    <visual>
      <origin
        xyz="0 0 0"
        rpy="0 0 0" />
      <geometry>
        <mesh
          filename="package://gf3_description/meshes/shoulder_2.STL" />
      </geometry>
      <material
        name="">
        <color
          rgba="0.752941176470588 0.752941176470588 0.752941176470588 1" />
      </material>
    </visual>
    <collision>
      <origin
        xyz="0 0 0"
        rpy="0 0 0" />
      <geometry>
        <mesh
          filename="package://gf3_description/meshes/shoulder_2.STL" />
      </geometry>
    </collision>
  </link>
  <joint
    name="shoulder_1_shoulder_2"
    type="continuous">
    <origin
      xyz="0.186 0.025012 0.7024"
      rpy="0 1.4155 -1.5708" />
    <parent
      link="shoulder_1" />
    <child
      link="shoulder_2" />
    <axis
      xyz="0 1 0" />
  </joint>
  <link
    name="shoulder_3">
    <inertial>
      <origin
        xyz="-0.0269092135761492 0.0640846252957541 -1.53289660409506E-08"
        rpy="0 0 0" />
      <mass
        value="0.370585135046895" />
      <inertia
        ixx="0.000523354390280425"
        ixy="6.02723287451794E-05"
        ixz="-9.62981343736503E-11"
        iyy="0.000290540478475071"
        iyz="-7.2434133454519E-11"
        izz="0.00040667010432906" />
    </inertial>
    <visual>
      <origin
        xyz="0 0 0"
        rpy="0 0 0" />
      <geometry>
        <mesh
          filename="package://gf3_description/meshes/shoulder_3.STL" />
      </geometry>
      <material
        name="">
        <color
          rgba="0.752941176470588 0.752941176470588 0.752941176470588 1" />
      </material>
    </visual>
    <collision>
      <origin
        xyz="0 0 0"
        rpy="0 0 0" />
      <geometry>
        <mesh
          filename="package://gf3_description/meshes/shoulder_3.STL" />
      </geometry>
    </collision>
  </link>
  <joint
    name="shoulder_2_shoulder_3"
    type="continuous">
    <origin
      xyz="-0.007733 0.1005 -0.049398"
      rpy="1.5708 0.15528 0" />
    <parent
      link="shoulder_2" />
    <child
      link="shoulder_3" />
    <axis
      xyz="0 1 0" />
  </joint>
  <link
    name="upper_arm">
    <inertial>
      <origin
        xyz="-2.88566393003009E-12 -0.0579636903882207 1.1743425676336E-11"
        rpy="0 0 0" />
      <mass
        value="0.079380694983881" />
      <inertia
        ixx="0.000349386865286372"
        ixy="1.01029048780009E-14"
        ixz="-3.89234678559516E-15"
        iyy="2.37717514500075E-05"
        iyz="-2.72966992972112E-14"
        izz="0.00034938686529665" />
    </inertial>
    <visual>
      <origin
        xyz="0 0 0"
        rpy="0 0 0" />
      <geometry>
        <mesh
          filename="package://gf3_description/meshes/upper_arm.STL" />
      </geometry>
      <material
        name="">
        <color
          rgba="0.752941176470588 0.752941176470588 0.752941176470588 1" />
      </material>
    </visual>
    <collision>
      <origin
        xyz="0 0 0"
        rpy="0 0 0" />
      <geometry>
        <mesh
          filename="package://gf3_description/meshes/upper_arm.STL" />
      </geometry>
    </collision>
  </link>
  <joint
    name="shoulder_3_upper_arm"
    type="continuous">
    <origin
      xyz="-0.0075 0.077 0"
      rpy="-3.1416 -0.30797 -1.5708" />
    <parent
      link="shoulder_3" />
    <child
      link="upper_arm" />
    <axis
      xyz="0 -1 0" />
  </joint>
</robot>